# Exception Handling in Python

This document covers the fundamental concepts of exception handling in Python, explaining what exceptions are, why they are important, and how to implement them in your code for more robust and user-friendly programs.

---

## What Are Exceptions?

Exceptions are a type of error that occurs *during the execution* of a program. Unlike **syntax errors**, which are mistakes in how you write the code and prevent the program from even starting, exceptions happen when your code is technically correct but encounters an unforeseen situation or invalid data at runtime.

*   **Syntactically Correct:** The Python interpreter understands your code structure.
*   **Runtime Issue:** The problem arises when the computer tries to perform an operation with specific values or conditions that make the operation impossible or invalid.
*   **External Factors:** Often, exceptions are caused by things outside the immediate program logic, such as incorrect user input or missing external resources (like files).

### Differentiating Exceptions from Syntax Errors

It's crucial to understand the difference:

*   **Syntax Error:** A mistake in the *grammar* or *structure* of your Python code. The program won't even start running.
    *   **Example:** Forgetting a closing bracket `)` or colon `:`.
    *   **Programmer's Mistake:** These are errors that the programmer must fix in the code itself.
*   **Exception:** The code is structured correctly, but an issue arises when the program is actually running, usually due to data or circumstances.
    *   **Example:** Trying to divide a number by zero. Mathematically impossible.
    *   **External/Runtime Issue:** Often not a flaw in the code's logic itself, but rather an unexpected condition.

---

## Common Types of Exceptions

Let's explore some common scenarios that lead to exceptions:

### 1. `ZeroDivisionError`

This occurs when you attempt to divide a number by zero.

*   **Scenario:** A program takes two numbers as input and divides them. If the second number entered by the user is `0`, a `ZeroDivisionError` will occur.
*   **Why it's an Exception:** The division operation `a / b` is syntactically correct Python. The problem only arises when `b` specifically holds the value `0`.

**Code Example:**

```python
# This code prompts for two numbers and divides them
num1 = int(input("Enter first number: "))
num2 = int(input("Enter second number: "))

result = num1 / num2
print("Division result:", result)
```

**How it works:**
*   **Valid Input (e.g., 20, 5):**
    ```
    Enter first number: 20
    Enter second number: 5
    Division result: 4.0
    ```
    The program runs perfectly, no error.
*   **Invalid Input (e.g., 20, 0):**
    ```
    Enter first number: 20
    Enter second number: 0
    Traceback (most recent call last):
      File "<stdin>", line 4, in <module>
    ZeroDivisionError: division by zero
    ```
    The `ZeroDivisionError` is raised because division by zero is mathematically undefined.

### 2. `NameError`

This occurs when you try to use a variable or function name that hasn't been defined yet.

*   **Scenario:** You attempt to print the value of a variable that was never assigned a value or referenced.
*   **Why it's an Exception:** The `print(variable_name)` statement is syntactically correct. The issue is that `variable_name` doesn't exist in the program's current scope at the time of execution.

**Code Example:**

```python
# This code defines 'c' but tries to print 'd'
a = 10
b = 2
c = a / b
print("Value of c:", c)
print("Value of d:", d) # 'd' is not defined
```

**How it works:**
*   **Execution:**
    ```
    Value of c: 5.0
    Traceback (most recent call last):
      File "<stdin>", line 6, in <module>
    NameError: name 'd' is not defined
    ```
    The program successfully calculates and prints `c`. However, when it reaches `print("Value of d:", d)`, it encounters `d` which has not been created.

### 3. `FileNotFoundError`

This occurs when your program tries to access a file that does not exist at the specified location.

*   **Scenario:** You write code to open a text file for reading, but the file is either named incorrectly or is not present in the expected directory.
*   **Why it's an Exception:** The `open("filename.txt", "r")` syntax is perfectly valid for opening files. The problem is an external one: the file itself isn't there.

**Code Example:**

```python
# This code tries to open a file that doesn't exist
file_handle = open("nonexistent_file.txt", "r")
print("File opened successfully!")
file_handle.close()
```

**How it works:**
*   **Execution:**
    ```
    Traceback (most recent call last):
      File "<stdin>", line 2, in <module>
    FileNotFoundError: [Errno 2] No such file or directory: 'nonexistent_file.txt'
    ```
    The program immediately stops when it tries to open "nonexistent_file.txt" because the operating system cannot find it.

---

## Why Handle Exceptions? (The Purpose)

The goal of exception handling is not to prevent the exceptional situation itself (e.g., you can't force 0 to be a non-zero number). Instead, it's about making your program *robust* and *user-friendly* when such situations occur.

*   **Graceful Termination:** Instead of crashing with a confusing "Traceback" message, the program can exit smoothly.
*   **Informative Messages:** Provide helpful feedback to the user, explaining what went wrong and how they might fix it (e.g., "Please enter a non-zero number for the divisor," or "The file you specified does not exist. Check the filename and try again.").
*   **Prevent Data Loss/Corruption:** Ensure that critical operations (like closing files) are performed even if other parts of the program fail.
*   **Maintain Program Flow:** Allow the program to continue running or attempt alternative actions, rather than stopping abruptly.

**The core idea:** When an exception happens, we want to *catch* it and *deal with it* in a controlled manner, rather than letting the program crash.

---

## The `try-except` Block

The `try-except` block is the primary mechanism for handling exceptions in Python. It allows you to "try" a piece of code that might cause an exception and "catch" specific exceptions if they occur.

### Basic Structure

```python
try:
    # Code that might raise an exception
    # (The "risky" code)
except ExceptionType:
    # Code to execute if ExceptionType occurs within the try block
    # (The "handling" code)
```

**How it Works:**

1.  **`try` block:** Python first attempts to execute the code inside the `try` block.
2.  **No Exception:** If no exception occurs, the `except` block is skipped, and the program continues after the `try-except` structure.
3.  **Exception Occurs:** If an exception *of the specified `ExceptionType`* occurs within the `try` block, Python immediately stops executing the rest of the `try` block and jumps to the corresponding `except ExceptionType` block.
4.  **Handling:** The code inside the `except` block is then executed to deal with the exception.
5.  **Uncaught Exception:** If an exception occurs in the `try` block *and there is no matching `except` block* to catch it, the program will terminate with a traceback (the default Python error behavior).

**Code Example (`ZeroDivisionError` handling):**

```python
num1 = int(input("Enter first number: "))
num2 = int(input("Enter second number: "))

try:
    result = num1 / num2
    print("Division result:", result)
except ZeroDivisionError:
    print("Error: Divisor cannot be zero. Please enter a non-zero number.")

print("Program continues after exception handling.")
```

**How it works:**
*   **Valid Input (e.g., 20, 5):**
    ```
    Enter first number: 20
    Enter second number: 5
    Division result: 4.0
    Program continues after exception handling.
    ```
    The `try` block executes successfully, `except` block is skipped.
*   **Invalid Input (e.g., 20, 0):**
    ```
    Enter first number: 20
    Enter second number: 0
    Error: Divisor cannot be zero. Please enter a non-zero number.
    Program continues after exception handling.
    ```
    The `ZeroDivisionError` is caught by the `except ZeroDivisionError` block, which prints a helpful message. The program then continues gracefully.

---

## Handling Multiple Specific Exceptions

You can specify multiple `except` blocks to handle different types of exceptions that might occur within the `try` block.

**Code Example (Handling `ZeroDivisionError` and `NameError`):**

```python
a = 4
b = 6 # For ZeroDivisionError example, change b to 0
# To trigger NameError, uncomment the line 'print(d)' and ensure 'd' is not defined elsewhere
# d = 0 # If this line is present, NameError won't occur for 'd'

try:
    result = a / b
    print("Division result:", result)
    # print(d) # Uncommenting this line will cause a NameError if 'd' is not defined
except ZeroDivisionError:
    print("Error: Invalid input, divisor cannot be 0.")
except NameError:
    print("Error: Variable not defined. Please check your code.")

print("End of program.")
```

**How it works:**
*   **No Exception (a=4, b=6):**
    ```
    Division result: 0.6666666666666666
    End of program.
    ```
*   **`ZeroDivisionError` (a=4, b=0):**
    ```
    Error: Invalid input, divisor cannot be 0.
    End of program.
    ```
*   **`NameError` (if `print(d)` is uncommented and `d` is not defined):**
    ```
    Error: Variable not defined. Please check your code.
    End of program.
    ```
    Python will check each `except` block in order until it finds one that matches the exception that occurred.

### Combining with `FileNotFoundError`

Let's integrate the file handling example:

**Code Example (Handling `ZeroDivisionError`, `NameError`, and `FileNotFoundError`):**

```python
# Ensure 'abc.txt' does NOT exist to trigger FileNotFoundError
# Create 'abc.txt' to see no error for file operation

try:
    # Attempt to open a file
    file_handle = open("abc.txt", "r")
    print("File 'abc.txt' opened successfully.")
    file_handle.close()

    # Attempt division
    num1 = 20
    num2 = 0 # Change to 4 to avoid ZeroDivisionError
    result = num1 / num2
    print("Division result:", result)

    # Attempt to print an undefined variable
    # print(undefined_variable) # Uncomment to trigger NameError

except ZeroDivisionError:
    print("Error: Cannot divide by zero.")
except NameError:
    print("Error: A variable used in the code is not defined.")
except FileNotFoundError:
    print("Error: The file specified does not exist. Please check the path and filename.")

print("Program finished.")
```

**How it works:**
*   If `abc.txt` doesn't exist, `FileNotFoundError` is caught.
*   If `abc.txt` exists but `num2` is 0, `ZeroDivisionError` is caught.
*   If `abc.txt` exists, `num2` is not 0, but `print(undefined_variable)` is uncommented, `NameError` is caught.
*   Only one `except` block matching the *first* exception that occurs will execute.

---

## The Generic `except` Block

What if you encounter an exception type you didn't explicitly list? Python offers a generic `except` block that catches *any* exception.

### Structure

```python
try:
    # Code that might raise an exception
except SpecificException1:
    # Handle SpecificException1
except SpecificException2:
    # Handle SpecificException2
except: # This catches ANY other exception
    # Generic error handling
    print("Something unexpected went wrong!")
```

*   **Placement:** The generic `except` block should *always* be the last `except` block. Python checks `except` blocks from top to bottom. If a generic `except` block comes first, it will catch all exceptions, and subsequent specific `except` blocks will never be reached.
*   **Usefulness:** There are many built-in exception types in Python (around 30 common ones). It's impractical to handle every single one. The generic `except` provides a fallback for unforeseen issues.

**Code Example:**

```python
try:
    num = int(input("Enter a number: "))
    result = 10 / num
    print("Result:", result)
    # If the user enters text instead of a number,
    # it will raise a ValueError, which is caught by the generic except.
except ZeroDivisionError:
    print("Cannot divide by zero.")
except: # Catches any other exception, including ValueError, TypeError etc.
    print("An unexpected error occurred. Please try again with valid input.")

print("Program finished.")
```

**How it works:**
*   **Input: `5`**
    ```
    Enter a number: 5
    Result: 2.0
    Program finished.
    ```
*   **Input: `0`**
    ```
    Enter a number: 0
    Cannot divide by zero.
    Program finished.
    ```
*   **Input: `hello` (causes `ValueError`)**
    ```
    Enter a number: hello
    An unexpected error occurred. Please try again with valid input.
    Program finished.
    ```
    Here, `ValueError` is not explicitly handled, but the generic `except` block catches it.

---

## The `finally` Block

Sometimes, you have code that *must* be executed regardless of whether an exception occurred or not. A common example is closing a file or releasing a network connection. The `finally` block ensures this happens.

### Structure

```python
try:
    # Code that might raise an exception
except SpecificException:
    # Handle the exception
finally:
    # Code that will ALWAYS execute,
    # whether an exception occurred or not, and whether it was handled or not.
```

**How it works:**

1.  **Guaranteed Execution:** The code within the `finally` block will always run, no matter what happens in the `try` or `except` blocks.
    *   If the `try` block completes successfully: `try` -> `finally`.
    *   If an exception occurs and is caught by an `except` block: `try` (exception) -> `except` -> `finally`.
    *   If an exception occurs and is *not* caught by any `except` block: `try` (exception) -> `finally` -> program terminates with traceback.
2.  **Resource Cleanup:** It is primarily used for cleanup operations, like closing files, database connections, or network sockets, to prevent resource leaks.

**Code Example (File Handling with `finally`):**

```python
file_handle = None # Initialize to None to ensure it exists if error happens before open()

try:
    # Try to open an existing file
    file_handle = open("my_data.txt", "w") # Open in write mode, creates if not exists
    file_handle.write("This is some data.\n")
    print("Data written to file.")

    # Now, try to cause an exception
    # For example, let's try to divide by zero here
    result = 10 / 0 # This will cause a ZeroDivisionError
    print("Result of division:", result)

except ZeroDivisionError:
    print("Caught a ZeroDivisionError!")
finally:
    # This block will always execute
    if file_handle: # Check if the file was actually opened
        file_handle.close()
        print("File closed in finally block.")
    else:
        print("File was not opened, so nothing to close.")

print("Program execution completed.")
```

**How it works:**
*   **No Exception (if `result = 10 / 2` instead):**
    ```
    Data written to file.
    Result of division: 5.0
    File closed in finally block.
    Program execution completed.
    ```
*   **With Exception (`ZeroDivisionError`):**
    ```
    Data written to file.
    Caught a ZeroDivisionError!
    File closed in finally block.
    Program execution completed.
    ```
    Even though the `ZeroDivisionError` occurred and was handled, the `finally` block still executed, ensuring the file was properly closed. This prevents the file from remaining open and potentially causing issues.

**Pain Point/Consideration:**
*   **Exception in `finally` block:** What happens if an exception occurs *within* the `finally` block itself? This is an advanced scenario to consider. Generally, code in `finally` should be robust and less prone to exceptions (e.g., just `close()` calls). If an exception does occur there, it would override any exception that was previously being handled from the `try` or `except` blocks, leading to a new traceback.

---

## User-Defined Exceptions (`raise`)

Sometimes, Python's built-in exceptions don't cover specific "logical" errors unique to your program's rules. In such cases, you can create and `raise` your own custom exceptions.

*   **Scenario:** You have a rule that a user's age must be 18 or older to vote. Python doesn't have a built-in "UnderAgeError."
*   **`print()` vs. `raise Exception()`:**
    *   `print("You are underage")` just displays a message and the program continues.
    *   `raise Exception("You are underage")` actively stops the program's normal flow (if not caught) and signals an exceptional event, similar to how Python raises built-in errors.

### Using the `raise` Keyword

You use the `raise` keyword followed by an exception object (often `Exception` or a more specific built-in exception, or your custom exception class) and an optional message.

**Code Example:**

```python
age = int(input("Enter your age: "))

if age < 18:
    # This creates and raises a generic Exception with a custom message
    raise Exception('You are underage, cannot vote!')
else:
    print("You are eligible to vote.")

print("Program continues (if no exception was raised).")
```

**How it works:**
*   **Valid Input (e.g., 25):**
    ```
    Enter your age: 25
    You are eligible to vote.
    Program continues (if no exception was raised).
    ```
*   **Invalid Input (e.g., 16):**
    ```
    Enter your age: 16
    Traceback (most recent call last):
      File "<stdin>", line 5, in <module>
    Exception: You are underage, cannot vote!
    ```
    Here, *our code* intentionally triggered an `Exception` because our custom condition (`age < 18`) was met. This behaves just like any other exception: if not caught, it stops the program.

You can then catch these user-defined exceptions using `try-except` blocks, just like built-in exceptions:

```python
try:
    age = int(input("Enter your age: "))
    if age < 18:
        raise Exception('You are underage, cannot vote!')
    else:
        print("You are eligible to vote.")
except Exception as e: # Catch the generic Exception type
    print(f"Caught an error: {e}")
    print("Please ensure you are 18 or older to vote.")

print("Program finished gracefully.")
```

**How it works:**
*   **Input: `16`**
    ```
    Enter your age: 16
    Caught an error: You are underage, cannot vote!
    Please ensure you are 18 or older to vote.
    Program finished gracefully.
    ```
    The `raise Exception` is now caught by our `except Exception` block, allowing us to provide a user-friendly message and for the program to terminate gracefully.

---

## Summary and Important Tips

### Summary

*   **Exceptions** are runtime errors that occur when a syntactically correct program encounters an unforeseen problem (e.g., bad input, missing files). They differ from **syntax errors** which prevent a program from running at all.
*   **Exception Handling** allows programs to deal with these unexpected situations gracefully, preventing crashes and providing helpful feedback to the user.
*   The **`try-except` block** is the core mechanism:
    *   Code that *might* cause an exception goes in the `try` block.
    *   Code to *handle* a specific exception (or any exception) goes in the `except` block.
*   You can have **multiple `except` blocks** to catch different types of exceptions.
*   A **generic `except` block** (without a specific exception type) can catch any unhandled exception. It should always be the last `except` block.
*   The **`finally` block** contains code that is *guaranteed* to execute, regardless of whether an exception occurred or was handled. It's crucial for resource cleanup (e.g., closing files).
*   The **`raise` keyword** allows you to create and trigger your own **user-defined exceptions** based on custom conditions in your program.

### Important Tips

1.  **Be Specific with `except` Blocks:** Try to catch specific exceptions whenever possible (e.g., `except ZeroDivisionError`). This helps you provide precise error messages and handle different problems appropriately.
2.  **Use Generic `except` Sparingly (and Last):** While useful for catching unknown errors, a generic `except` can hide bugs. Use it as a last resort, and always place it after more specific `except` blocks.
3.  **Provide Informative Messages:** The goal is to help the user. Error messages should be clear, concise, and ideally suggest a solution or next step.
4.  **Prioritize Resource Cleanup with `finally`:** Always use `finally` to ensure that resources like files, network connections, or database handles are properly closed or released, even if an error occurs.
5.  **Don't Overuse Exception Handling:** Not every conditional check needs to be an exception. If you can anticipate a condition and handle it with a simple `if-else` statement (e.g., checking if a list is empty before accessing an element), that's often clearer than raising and catching an exception. Exceptions are for *exceptional* circumstances.
6.  **Practice:** Review your previous programs and identify areas where exception handling could make them more robust and user-friendly. This is a crucial skill for writing professional-grade software.